{
 "cells": [
  {
   "cell_type": "code",
   "execution_count": 1,
   "metadata": {},
   "outputs": [],
   "source": [
    "import os, shutil"
   ]
  },
  {
   "cell_type": "code",
   "execution_count": 21,
   "metadata": {},
   "outputs": [],
   "source": [
    "original_dataset_dir = '/home/ubuntu/deep-chollet/train'\n",
    "\n",
    "base_dir = '/home/ubuntu/deep-chollet/cats_and_dogs_small'\n",
    "os.mkdir(base_dir)"
   ]
  },
  {
   "cell_type": "code",
   "execution_count": 22,
   "metadata": {},
   "outputs": [],
   "source": [
    "train_dir = os.path.join(base_dir, 'train')\n",
    "os.mkdir(train_dir)\n",
    "validation_dir = os.path.join(base_dir, 'validation')\n",
    "os.mkdir(validation_dir)\n",
    "test_dir = os.path.join(base_dir, 'test')\n",
    "os.mkdir(test_dir)\n",
    "\n",
    "train_cats_dir = os.path.join(train_dir, 'cats')\n",
    "os.mkdir(train_cats_dir)\n",
    "train_dogs_dir = os.path.join(train_dir, 'dogs')\n",
    "os.mkdir(train_dogs_dir)\n",
    "\n",
    "validation_cats_dir = os.path.join(validation_dir, 'cats')\n",
    "os.mkdir(validation_cats_dir)\n",
    "validation_dogs_dir = os.path.join(validation_dir, 'dogs')\n",
    "os.mkdir(validation_dogs_dir)\n",
    "\n",
    "test_cats_dir = os.path.join(test_dir, 'cats')\n",
    "os.mkdir(test_cats_dir)\n",
    "test_dogs_dir = os.path.join(test_dir, 'dogs')\n",
    "os.mkdir(test_dogs_dir)"
   ]
  },
  {
   "cell_type": "code",
   "execution_count": 23,
   "metadata": {},
   "outputs": [],
   "source": [
    "fnames = ['cat.{}.jpg'.format(i) for i in range(1000)]\n",
    "for fname in fnames:\n",
    "    src = os.path.join(original_dataset_dir, fname)\n",
    "    dst = os.path.join(train_cats_dir, fname)\n",
    "    shutil.copyfile(src, dst)\n",
    "\n",
    "fnames = ['cat.{}.jpg'.format(i) for i in range(1000, 1500)]\n",
    "for fname in fnames:\n",
    "    src = os.path.join(original_dataset_dir, fname)\n",
    "    dst = os.path.join(validation_cats_dir, fname)\n",
    "    shutil.copyfile(src, dst)\n",
    "    \n",
    "fnames = ['cat.{}.jpg'.format(i) for i in range(1500, 2000)]\n",
    "for fname in fnames:\n",
    "    src = os.path.join(original_dataset_dir, fname)\n",
    "    dst = os.path.join(test_cats_dir, fname)\n",
    "    shutil.copyfile(src, dst)\n",
    "    \n",
    "fnames = ['dog.{}.jpg'.format(i) for i in range(1000)]\n",
    "for fname in fnames:\n",
    "    src = os.path.join(original_dataset_dir, fname)\n",
    "    dst = os.path.join(train_dogs_dir, fname)\n",
    "    shutil.copyfile(src, dst)\n",
    "    \n",
    "fnames = ['dog.{}.jpg'.format(i) for i in range(1000, 1500)]\n",
    "for fname in fnames:\n",
    "    src = os.path.join(original_dataset_dir, fname)\n",
    "    dst = os.path.join(validation_dogs_dir, fname)\n",
    "    shutil.copyfile(src, dst)\n",
    "    \n",
    "fnames = ['dog.{}.jpg'.format(i) for i in range(1500, 2000)]\n",
    "for fname in fnames:\n",
    "    src = os.path.join(original_dataset_dir, fname)\n",
    "    dst = os.path.join(test_dogs_dir, fname)\n",
    "    shutil.copyfile(src, dst)"
   ]
  },
  {
   "cell_type": "code",
   "execution_count": 24,
   "metadata": {},
   "outputs": [
    {
     "data": {
      "text/plain": [
       "1000"
      ]
     },
     "execution_count": 24,
     "metadata": {},
     "output_type": "execute_result"
    }
   ],
   "source": [
    "len(os.listdir(train_cats_dir))"
   ]
  },
  {
   "cell_type": "code",
   "execution_count": 25,
   "metadata": {},
   "outputs": [
    {
     "data": {
      "text/plain": [
       "1000"
      ]
     },
     "execution_count": 25,
     "metadata": {},
     "output_type": "execute_result"
    }
   ],
   "source": [
    "len(os.listdir(train_dogs_dir))"
   ]
  },
  {
   "cell_type": "code",
   "execution_count": 26,
   "metadata": {},
   "outputs": [
    {
     "data": {
      "text/plain": [
       "500"
      ]
     },
     "execution_count": 26,
     "metadata": {},
     "output_type": "execute_result"
    }
   ],
   "source": [
    "len(os.listdir(validation_cats_dir))"
   ]
  },
  {
   "cell_type": "code",
   "execution_count": 27,
   "metadata": {},
   "outputs": [
    {
     "data": {
      "text/plain": [
       "500"
      ]
     },
     "execution_count": 27,
     "metadata": {},
     "output_type": "execute_result"
    }
   ],
   "source": [
    "len(os.listdir(validation_dogs_dir))"
   ]
  },
  {
   "cell_type": "code",
   "execution_count": 31,
   "metadata": {},
   "outputs": [
    {
     "name": "stdout",
     "output_type": "stream",
     "text": [
      "total test cat images: 500\n"
     ]
    }
   ],
   "source": [
    "print('total test cat images:', len(os.listdir(test_cats_dir)))"
   ]
  },
  {
   "cell_type": "code",
   "execution_count": 30,
   "metadata": {},
   "outputs": [
    {
     "name": "stdout",
     "output_type": "stream",
     "text": [
      "total test dog images: 500\n"
     ]
    }
   ],
   "source": [
    "print('total test dog images:', len(os.listdir(test_dogs_dir)))"
   ]
  },
  {
   "cell_type": "code",
   "execution_count": 32,
   "metadata": {},
   "outputs": [
    {
     "name": "stderr",
     "output_type": "stream",
     "text": [
      "/home/ubuntu/anaconda3/envs/tensorflow_p36/lib/python3.6/site-packages/h5py/__init__.py:36: FutureWarning: Conversion of the second argument of issubdtype from `float` to `np.floating` is deprecated. In future, it will be treated as `np.float64 == np.dtype(float).type`.\n",
      "  from ._conv import register_converters as _register_converters\n",
      "Using TensorFlow backend.\n",
      "ERROR:root:Internal Python error in the inspect module.\n",
      "Below is the traceback from this internal error.\n",
      "\n",
      "ERROR:root:Internal Python error in the inspect module.\n",
      "Below is the traceback from this internal error.\n",
      "\n"
     ]
    },
    {
     "name": "stdout",
     "output_type": "stream",
     "text": [
      "Traceback (most recent call last):\n",
      "  File \"/home/ubuntu/anaconda3/envs/tensorflow_p36/lib/python3.6/pkgutil.py\", line 412, in get_importer\n",
      "    importer = sys.path_importer_cache[path_item]\n",
      "KeyError: ''\n",
      "\n",
      "During handling of the above exception, another exception occurred:\n",
      "\n",
      "Traceback (most recent call last):\n",
      "  File \"/home/ubuntu/anaconda3/envs/tensorflow_p36/lib/python3.6/site-packages/IPython/core/interactiveshell.py\", line 2963, in run_code\n",
      "    exec(code_obj, self.user_global_ns, self.user_ns)\n",
      "  File \"<ipython-input-32-6a4011829541>\", line 1, in <module>\n",
      "    from keras import layers\n",
      "  File \"/home/ubuntu/anaconda3/envs/tensorflow_p36/lib/python3.6/site-packages/keras/__init__.py\", line 3, in <module>\n",
      "    from . import utils\n",
      "  File \"/home/ubuntu/anaconda3/envs/tensorflow_p36/lib/python3.6/site-packages/keras/utils/__init__.py\", line 6, in <module>\n",
      "    from . import conv_utils\n",
      "  File \"/home/ubuntu/anaconda3/envs/tensorflow_p36/lib/python3.6/site-packages/keras/utils/conv_utils.py\", line 9, in <module>\n",
      "    from .. import backend as K\n",
      "  File \"/home/ubuntu/anaconda3/envs/tensorflow_p36/lib/python3.6/site-packages/keras/backend/__init__.py\", line 87, in <module>\n",
      "    from .tensorflow_backend import *\n",
      "  File \"/home/ubuntu/anaconda3/envs/tensorflow_p36/lib/python3.6/site-packages/keras/backend/tensorflow_backend.py\", line 5, in <module>\n",
      "    import tensorflow as tf\n",
      "  File \"/home/ubuntu/anaconda3/envs/tensorflow_p36/lib/python3.6/site-packages/tensorflow/__init__.py\", line 24, in <module>\n",
      "    from tensorflow.python import pywrap_tensorflow  # pylint: disable=unused-import\n",
      "  File \"/home/ubuntu/anaconda3/envs/tensorflow_p36/lib/python3.6/site-packages/tensorflow/python/__init__.py\", line 52, in <module>\n",
      "    from tensorflow.core.framework.graph_pb2 import *\n",
      "  File \"/home/ubuntu/anaconda3/envs/tensorflow_p36/lib/python3.6/site-packages/tensorflow/core/framework/graph_pb2.py\", line 6, in <module>\n",
      "    from google.protobuf import descriptor as _descriptor\n",
      "  File \"/home/ubuntu/anaconda3/envs/tensorflow_p36/lib/python3.6/site-packages/google/protobuf/__init__.py\", line 37, in <module>\n",
      "    __import__('pkg_resources').declare_namespace(__name__)\n",
      "  File \"/home/ubuntu/anaconda3/envs/tensorflow_p36/lib/python3.6/site-packages/pkg_resources/__init__.py\", line 3095, in <module>\n",
      "    @_call_aside\n",
      "  File \"/home/ubuntu/anaconda3/envs/tensorflow_p36/lib/python3.6/site-packages/pkg_resources/__init__.py\", line 3079, in _call_aside\n",
      "    f(*args, **kwargs)\n",
      "  File \"/home/ubuntu/anaconda3/envs/tensorflow_p36/lib/python3.6/site-packages/pkg_resources/__init__.py\", line 3108, in _initialize_master_working_set\n",
      "    working_set = WorkingSet._build_master()\n",
      "  File \"/home/ubuntu/anaconda3/envs/tensorflow_p36/lib/python3.6/site-packages/pkg_resources/__init__.py\", line 561, in _build_master\n",
      "    ws = cls()\n",
      "  File \"/home/ubuntu/anaconda3/envs/tensorflow_p36/lib/python3.6/site-packages/pkg_resources/__init__.py\", line 554, in __init__\n",
      "    self.add_entry(entry)\n",
      "  File \"/home/ubuntu/anaconda3/envs/tensorflow_p36/lib/python3.6/site-packages/pkg_resources/__init__.py\", line 610, in add_entry\n",
      "    for dist in find_distributions(entry, True):\n",
      "  File \"/home/ubuntu/anaconda3/envs/tensorflow_p36/lib/python3.6/site-packages/pkg_resources/__init__.py\", line 1862, in find_distributions\n",
      "    importer = get_importer(path_item)\n",
      "  File \"/home/ubuntu/anaconda3/envs/tensorflow_p36/lib/python3.6/pkgutil.py\", line 416, in get_importer\n",
      "    importer = path_hook(path_item)\n",
      "  File \"<frozen importlib._bootstrap_external>\", line 1324, in path_hook_for_FileFinder\n",
      "  File \"<frozen importlib._bootstrap_external>\", line 102, in _path_isdir\n",
      "FileNotFoundError: [Errno 2] No such file or directory\n",
      "\n",
      "During handling of the above exception, another exception occurred:\n",
      "\n",
      "Traceback (most recent call last):\n",
      "  File \"/home/ubuntu/anaconda3/envs/tensorflow_p36/lib/python3.6/site-packages/IPython/core/interactiveshell.py\", line 1863, in showtraceback\n",
      "    stb = value._render_traceback_()\n",
      "AttributeError: 'FileNotFoundError' object has no attribute '_render_traceback_'\n",
      "\n",
      "During handling of the above exception, another exception occurred:\n",
      "\n",
      "Traceback (most recent call last):\n",
      "  File \"/home/ubuntu/anaconda3/envs/tensorflow_p36/lib/python3.6/site-packages/IPython/core/ultratb.py\", line 1095, in get_records\n",
      "    return _fixed_getinnerframes(etb, number_of_lines_of_context, tb_offset)\n",
      "  File \"/home/ubuntu/anaconda3/envs/tensorflow_p36/lib/python3.6/site-packages/IPython/core/ultratb.py\", line 311, in wrapped\n",
      "    return f(*args, **kwargs)\n",
      "  File \"/home/ubuntu/anaconda3/envs/tensorflow_p36/lib/python3.6/site-packages/IPython/core/ultratb.py\", line 345, in _fixed_getinnerframes\n",
      "    records = fix_frame_records_filenames(inspect.getinnerframes(etb, context))\n",
      "  File \"/home/ubuntu/anaconda3/envs/tensorflow_p36/lib/python3.6/inspect.py\", line 1483, in getinnerframes\n",
      "    frameinfo = (tb.tb_frame,) + getframeinfo(tb, context)\n",
      "  File \"/home/ubuntu/anaconda3/envs/tensorflow_p36/lib/python3.6/inspect.py\", line 1441, in getframeinfo\n",
      "    filename = getsourcefile(frame) or getfile(frame)\n",
      "  File \"/home/ubuntu/anaconda3/envs/tensorflow_p36/lib/python3.6/inspect.py\", line 696, in getsourcefile\n",
      "    if getattr(getmodule(object, filename), '__loader__', None) is not None:\n",
      "  File \"/home/ubuntu/anaconda3/envs/tensorflow_p36/lib/python3.6/inspect.py\", line 725, in getmodule\n",
      "    file = getabsfile(object, _filename)\n",
      "  File \"/home/ubuntu/anaconda3/envs/tensorflow_p36/lib/python3.6/inspect.py\", line 709, in getabsfile\n",
      "    return os.path.normcase(os.path.abspath(_filename))\n",
      "  File \"/home/ubuntu/anaconda3/envs/tensorflow_p36/lib/python3.6/posixpath.py\", line 376, in abspath\n",
      "    cwd = os.getcwd()\n",
      "FileNotFoundError: [Errno 2] No such file or directory\n",
      "Traceback (most recent call last):\n",
      "  File \"/home/ubuntu/anaconda3/envs/tensorflow_p36/lib/python3.6/pkgutil.py\", line 412, in get_importer\n",
      "    importer = sys.path_importer_cache[path_item]\n",
      "KeyError: ''\n",
      "\n",
      "During handling of the above exception, another exception occurred:\n",
      "\n",
      "Traceback (most recent call last):\n",
      "  File \"/home/ubuntu/anaconda3/envs/tensorflow_p36/lib/python3.6/site-packages/IPython/core/interactiveshell.py\", line 2963, in run_code\n",
      "    exec(code_obj, self.user_global_ns, self.user_ns)\n",
      "  File \"<ipython-input-32-6a4011829541>\", line 1, in <module>\n",
      "    from keras import layers\n",
      "  File \"/home/ubuntu/anaconda3/envs/tensorflow_p36/lib/python3.6/site-packages/keras/__init__.py\", line 3, in <module>\n",
      "    from . import utils\n",
      "  File \"/home/ubuntu/anaconda3/envs/tensorflow_p36/lib/python3.6/site-packages/keras/utils/__init__.py\", line 6, in <module>\n",
      "    from . import conv_utils\n",
      "  File \"/home/ubuntu/anaconda3/envs/tensorflow_p36/lib/python3.6/site-packages/keras/utils/conv_utils.py\", line 9, in <module>\n",
      "    from .. import backend as K\n",
      "  File \"/home/ubuntu/anaconda3/envs/tensorflow_p36/lib/python3.6/site-packages/keras/backend/__init__.py\", line 87, in <module>\n",
      "    from .tensorflow_backend import *\n",
      "  File \"/home/ubuntu/anaconda3/envs/tensorflow_p36/lib/python3.6/site-packages/keras/backend/tensorflow_backend.py\", line 5, in <module>\n",
      "    import tensorflow as tf\n",
      "  File \"/home/ubuntu/anaconda3/envs/tensorflow_p36/lib/python3.6/site-packages/tensorflow/__init__.py\", line 24, in <module>\n",
      "    from tensorflow.python import pywrap_tensorflow  # pylint: disable=unused-import\n",
      "  File \"/home/ubuntu/anaconda3/envs/tensorflow_p36/lib/python3.6/site-packages/tensorflow/python/__init__.py\", line 52, in <module>\n",
      "    from tensorflow.core.framework.graph_pb2 import *\n",
      "  File \"/home/ubuntu/anaconda3/envs/tensorflow_p36/lib/python3.6/site-packages/tensorflow/core/framework/graph_pb2.py\", line 6, in <module>\n",
      "    from google.protobuf import descriptor as _descriptor\n",
      "  File \"/home/ubuntu/anaconda3/envs/tensorflow_p36/lib/python3.6/site-packages/google/protobuf/__init__.py\", line 37, in <module>\n",
      "    __import__('pkg_resources').declare_namespace(__name__)\n",
      "  File \"/home/ubuntu/anaconda3/envs/tensorflow_p36/lib/python3.6/site-packages/pkg_resources/__init__.py\", line 3095, in <module>\n",
      "    @_call_aside\n",
      "  File \"/home/ubuntu/anaconda3/envs/tensorflow_p36/lib/python3.6/site-packages/pkg_resources/__init__.py\", line 3079, in _call_aside\n",
      "    f(*args, **kwargs)\n",
      "  File \"/home/ubuntu/anaconda3/envs/tensorflow_p36/lib/python3.6/site-packages/pkg_resources/__init__.py\", line 3108, in _initialize_master_working_set\n",
      "    working_set = WorkingSet._build_master()\n",
      "  File \"/home/ubuntu/anaconda3/envs/tensorflow_p36/lib/python3.6/site-packages/pkg_resources/__init__.py\", line 561, in _build_master\n",
      "    ws = cls()\n",
      "  File \"/home/ubuntu/anaconda3/envs/tensorflow_p36/lib/python3.6/site-packages/pkg_resources/__init__.py\", line 554, in __init__\n",
      "    self.add_entry(entry)\n",
      "  File \"/home/ubuntu/anaconda3/envs/tensorflow_p36/lib/python3.6/site-packages/pkg_resources/__init__.py\", line 610, in add_entry\n",
      "    for dist in find_distributions(entry, True):\n",
      "  File \"/home/ubuntu/anaconda3/envs/tensorflow_p36/lib/python3.6/site-packages/pkg_resources/__init__.py\", line 1862, in find_distributions\n",
      "    importer = get_importer(path_item)\n",
      "  File \"/home/ubuntu/anaconda3/envs/tensorflow_p36/lib/python3.6/pkgutil.py\", line 416, in get_importer\n",
      "    importer = path_hook(path_item)\n",
      "  File \"<frozen importlib._bootstrap_external>\", line 1324, in path_hook_for_FileFinder\n",
      "  File \"<frozen importlib._bootstrap_external>\", line 102, in _path_isdir\n",
      "FileNotFoundError: [Errno 2] No such file or directory\n",
      "\n",
      "During handling of the above exception, another exception occurred:\n",
      "\n",
      "Traceback (most recent call last):\n",
      "  File \"/home/ubuntu/anaconda3/envs/tensorflow_p36/lib/python3.6/site-packages/IPython/core/interactiveshell.py\", line 1863, in showtraceback\n",
      "    stb = value._render_traceback_()\n",
      "AttributeError: 'FileNotFoundError' object has no attribute '_render_traceback_'\n",
      "\n",
      "During handling of the above exception, another exception occurred:\n",
      "\n",
      "Traceback (most recent call last):\n",
      "  File \"/home/ubuntu/anaconda3/envs/tensorflow_p36/lib/python3.6/site-packages/IPython/core/interactiveshell.py\", line 2903, in run_ast_nodes\n",
      "    if self.run_code(code, result):\n",
      "  File \"/home/ubuntu/anaconda3/envs/tensorflow_p36/lib/python3.6/site-packages/IPython/core/interactiveshell.py\", line 2980, in run_code\n",
      "    self.showtraceback(running_compiled_code=True)\n",
      "  File \"/home/ubuntu/anaconda3/envs/tensorflow_p36/lib/python3.6/site-packages/IPython/core/interactiveshell.py\", line 1866, in showtraceback\n",
      "    value, tb, tb_offset=tb_offset)\n",
      "  File \"/home/ubuntu/anaconda3/envs/tensorflow_p36/lib/python3.6/site-packages/IPython/core/ultratb.py\", line 1373, in structured_traceback\n",
      "    self, etype, value, tb, tb_offset, number_of_lines_of_context)\n",
      "  File \"/home/ubuntu/anaconda3/envs/tensorflow_p36/lib/python3.6/site-packages/IPython/core/ultratb.py\", line 1281, in structured_traceback\n",
      "    self, etype, value, tb, tb_offset, number_of_lines_of_context\n",
      "  File \"/home/ubuntu/anaconda3/envs/tensorflow_p36/lib/python3.6/site-packages/IPython/core/ultratb.py\", line 1144, in structured_traceback\n",
      "    formatted_exceptions += self.prepare_chained_exception_message(evalue.__cause__)\n",
      "TypeError: must be str, not list\n",
      "\n",
      "During handling of the above exception, another exception occurred:\n",
      "\n",
      "Traceback (most recent call last):\n",
      "  File \"/home/ubuntu/anaconda3/envs/tensorflow_p36/lib/python3.6/site-packages/IPython/core/interactiveshell.py\", line 1863, in showtraceback\n",
      "    stb = value._render_traceback_()\n",
      "AttributeError: 'TypeError' object has no attribute '_render_traceback_'\n",
      "\n",
      "During handling of the above exception, another exception occurred:\n",
      "\n",
      "Traceback (most recent call last):\n",
      "  File \"/home/ubuntu/anaconda3/envs/tensorflow_p36/lib/python3.6/site-packages/IPython/core/ultratb.py\", line 1095, in get_records\n",
      "    return _fixed_getinnerframes(etb, number_of_lines_of_context, tb_offset)\n",
      "  File \"/home/ubuntu/anaconda3/envs/tensorflow_p36/lib/python3.6/site-packages/IPython/core/ultratb.py\", line 311, in wrapped\n",
      "    return f(*args, **kwargs)\n",
      "  File \"/home/ubuntu/anaconda3/envs/tensorflow_p36/lib/python3.6/site-packages/IPython/core/ultratb.py\", line 345, in _fixed_getinnerframes\n",
      "    records = fix_frame_records_filenames(inspect.getinnerframes(etb, context))\n",
      "  File \"/home/ubuntu/anaconda3/envs/tensorflow_p36/lib/python3.6/inspect.py\", line 1483, in getinnerframes\n",
      "    frameinfo = (tb.tb_frame,) + getframeinfo(tb, context)\n",
      "  File \"/home/ubuntu/anaconda3/envs/tensorflow_p36/lib/python3.6/inspect.py\", line 1441, in getframeinfo\n",
      "    filename = getsourcefile(frame) or getfile(frame)\n",
      "  File \"/home/ubuntu/anaconda3/envs/tensorflow_p36/lib/python3.6/inspect.py\", line 696, in getsourcefile\n",
      "    if getattr(getmodule(object, filename), '__loader__', None) is not None:\n",
      "  File \"/home/ubuntu/anaconda3/envs/tensorflow_p36/lib/python3.6/inspect.py\", line 725, in getmodule\n",
      "    file = getabsfile(object, _filename)\n",
      "  File \"/home/ubuntu/anaconda3/envs/tensorflow_p36/lib/python3.6/inspect.py\", line 709, in getabsfile\n",
      "    return os.path.normcase(os.path.abspath(_filename))\n",
      "  File \"/home/ubuntu/anaconda3/envs/tensorflow_p36/lib/python3.6/posixpath.py\", line 376, in abspath\n",
      "    cwd = os.getcwd()\n",
      "FileNotFoundError: [Errno 2] No such file or directory\n"
     ]
    },
    {
     "ename": "TypeError",
     "evalue": "must be str, not list",
     "output_type": "error",
     "traceback": [
      "\u001b[0;31m---------------------------------------------------------------------------\u001b[0m",
      "\u001b[0;31mKeyError\u001b[0m                                  Traceback (most recent call last)",
      "\u001b[0;32m~/anaconda3/envs/tensorflow_p36/lib/python3.6/pkgutil.py\u001b[0m in \u001b[0;36mget_importer\u001b[0;34m(path_item)\u001b[0m\n\u001b[1;32m    411\u001b[0m     \u001b[0;32mtry\u001b[0m\u001b[0;34m:\u001b[0m\u001b[0;34m\u001b[0m\u001b[0m\n\u001b[0;32m--> 412\u001b[0;31m         \u001b[0mimporter\u001b[0m \u001b[0;34m=\u001b[0m \u001b[0msys\u001b[0m\u001b[0;34m.\u001b[0m\u001b[0mpath_importer_cache\u001b[0m\u001b[0;34m[\u001b[0m\u001b[0mpath_item\u001b[0m\u001b[0;34m]\u001b[0m\u001b[0;34m\u001b[0m\u001b[0m\n\u001b[0m\u001b[1;32m    413\u001b[0m     \u001b[0;32mexcept\u001b[0m \u001b[0mKeyError\u001b[0m\u001b[0;34m:\u001b[0m\u001b[0;34m\u001b[0m\u001b[0m\n",
      "\u001b[0;31mKeyError\u001b[0m: ''",
      "\nDuring handling of the above exception, another exception occurred:\n",
      "\nDuring handling of the above exception, another exception occurred:\n",
      "\u001b[0;31mAttributeError\u001b[0m                            Traceback (most recent call last)",
      "\u001b[0;32m~/anaconda3/envs/tensorflow_p36/lib/python3.6/site-packages/IPython/core/interactiveshell.py\u001b[0m in \u001b[0;36mshowtraceback\u001b[0;34m(self, exc_tuple, filename, tb_offset, exception_only, running_compiled_code)\u001b[0m\n\u001b[1;32m   1862\u001b[0m                         \u001b[0;31m# in the engines. This should return a list of strings.\u001b[0m\u001b[0;34m\u001b[0m\u001b[0;34m\u001b[0m\u001b[0m\n\u001b[0;32m-> 1863\u001b[0;31m                         \u001b[0mstb\u001b[0m \u001b[0;34m=\u001b[0m \u001b[0mvalue\u001b[0m\u001b[0;34m.\u001b[0m\u001b[0m_render_traceback_\u001b[0m\u001b[0;34m(\u001b[0m\u001b[0;34m)\u001b[0m\u001b[0;34m\u001b[0m\u001b[0m\n\u001b[0m\u001b[1;32m   1864\u001b[0m                     \u001b[0;32mexcept\u001b[0m \u001b[0mException\u001b[0m\u001b[0;34m:\u001b[0m\u001b[0;34m\u001b[0m\u001b[0m\n",
      "\u001b[0;31mAttributeError\u001b[0m: 'FileNotFoundError' object has no attribute '_render_traceback_'",
      "\nDuring handling of the above exception, another exception occurred:\n",
      "\u001b[0;31mTypeError\u001b[0m                                 Traceback (most recent call last)",
      "\u001b[0;32m~/anaconda3/envs/tensorflow_p36/lib/python3.6/site-packages/IPython/core/interactiveshell.py\u001b[0m in \u001b[0;36mrun_code\u001b[0;34m(self, code_obj, result)\u001b[0m\n\u001b[1;32m   2978\u001b[0m             \u001b[0;32mif\u001b[0m \u001b[0mresult\u001b[0m \u001b[0;32mis\u001b[0m \u001b[0;32mnot\u001b[0m \u001b[0;32mNone\u001b[0m\u001b[0;34m:\u001b[0m\u001b[0;34m\u001b[0m\u001b[0m\n\u001b[1;32m   2979\u001b[0m                 \u001b[0mresult\u001b[0m\u001b[0;34m.\u001b[0m\u001b[0merror_in_exec\u001b[0m \u001b[0;34m=\u001b[0m \u001b[0msys\u001b[0m\u001b[0;34m.\u001b[0m\u001b[0mexc_info\u001b[0m\u001b[0;34m(\u001b[0m\u001b[0;34m)\u001b[0m\u001b[0;34m[\u001b[0m\u001b[0;36m1\u001b[0m\u001b[0;34m]\u001b[0m\u001b[0;34m\u001b[0m\u001b[0m\n\u001b[0;32m-> 2980\u001b[0;31m             \u001b[0mself\u001b[0m\u001b[0;34m.\u001b[0m\u001b[0mshowtraceback\u001b[0m\u001b[0;34m(\u001b[0m\u001b[0mrunning_compiled_code\u001b[0m\u001b[0;34m=\u001b[0m\u001b[0;32mTrue\u001b[0m\u001b[0;34m)\u001b[0m\u001b[0;34m\u001b[0m\u001b[0m\n\u001b[0m\u001b[1;32m   2981\u001b[0m         \u001b[0;32melse\u001b[0m\u001b[0;34m:\u001b[0m\u001b[0;34m\u001b[0m\u001b[0m\n\u001b[1;32m   2982\u001b[0m             \u001b[0moutflag\u001b[0m \u001b[0;34m=\u001b[0m \u001b[0;32mFalse\u001b[0m\u001b[0;34m\u001b[0m\u001b[0m\n",
      "\u001b[0;32m~/anaconda3/envs/tensorflow_p36/lib/python3.6/site-packages/IPython/core/interactiveshell.py\u001b[0m in \u001b[0;36mshowtraceback\u001b[0;34m(self, exc_tuple, filename, tb_offset, exception_only, running_compiled_code)\u001b[0m\n\u001b[1;32m   1864\u001b[0m                     \u001b[0;32mexcept\u001b[0m \u001b[0mException\u001b[0m\u001b[0;34m:\u001b[0m\u001b[0;34m\u001b[0m\u001b[0m\n\u001b[1;32m   1865\u001b[0m                         stb = self.InteractiveTB.structured_traceback(etype,\n\u001b[0;32m-> 1866\u001b[0;31m                                             value, tb, tb_offset=tb_offset)\n\u001b[0m\u001b[1;32m   1867\u001b[0m \u001b[0;34m\u001b[0m\u001b[0m\n\u001b[1;32m   1868\u001b[0m                     \u001b[0mself\u001b[0m\u001b[0;34m.\u001b[0m\u001b[0m_showtraceback\u001b[0m\u001b[0;34m(\u001b[0m\u001b[0metype\u001b[0m\u001b[0;34m,\u001b[0m \u001b[0mvalue\u001b[0m\u001b[0;34m,\u001b[0m \u001b[0mstb\u001b[0m\u001b[0;34m)\u001b[0m\u001b[0;34m\u001b[0m\u001b[0m\n",
      "\u001b[0;32m~/anaconda3/envs/tensorflow_p36/lib/python3.6/site-packages/IPython/core/ultratb.py\u001b[0m in \u001b[0;36mstructured_traceback\u001b[0;34m(self, etype, value, tb, tb_offset, number_of_lines_of_context)\u001b[0m\n\u001b[1;32m   1371\u001b[0m         \u001b[0mself\u001b[0m\u001b[0;34m.\u001b[0m\u001b[0mtb\u001b[0m \u001b[0;34m=\u001b[0m \u001b[0mtb\u001b[0m\u001b[0;34m\u001b[0m\u001b[0m\n\u001b[1;32m   1372\u001b[0m         return FormattedTB.structured_traceback(\n\u001b[0;32m-> 1373\u001b[0;31m             self, etype, value, tb, tb_offset, number_of_lines_of_context)\n\u001b[0m\u001b[1;32m   1374\u001b[0m \u001b[0;34m\u001b[0m\u001b[0m\n\u001b[1;32m   1375\u001b[0m \u001b[0;34m\u001b[0m\u001b[0m\n",
      "\u001b[0;32m~/anaconda3/envs/tensorflow_p36/lib/python3.6/site-packages/IPython/core/ultratb.py\u001b[0m in \u001b[0;36mstructured_traceback\u001b[0;34m(self, etype, value, tb, tb_offset, number_of_lines_of_context)\u001b[0m\n\u001b[1;32m   1279\u001b[0m             \u001b[0;31m# Verbose modes need a full traceback\u001b[0m\u001b[0;34m\u001b[0m\u001b[0;34m\u001b[0m\u001b[0m\n\u001b[1;32m   1280\u001b[0m             return VerboseTB.structured_traceback(\n\u001b[0;32m-> 1281\u001b[0;31m                 \u001b[0mself\u001b[0m\u001b[0;34m,\u001b[0m \u001b[0metype\u001b[0m\u001b[0;34m,\u001b[0m \u001b[0mvalue\u001b[0m\u001b[0;34m,\u001b[0m \u001b[0mtb\u001b[0m\u001b[0;34m,\u001b[0m \u001b[0mtb_offset\u001b[0m\u001b[0;34m,\u001b[0m \u001b[0mnumber_of_lines_of_context\u001b[0m\u001b[0;34m\u001b[0m\u001b[0m\n\u001b[0m\u001b[1;32m   1282\u001b[0m             )\n\u001b[1;32m   1283\u001b[0m         \u001b[0;32melse\u001b[0m\u001b[0;34m:\u001b[0m\u001b[0;34m\u001b[0m\u001b[0m\n",
      "\u001b[0;32m~/anaconda3/envs/tensorflow_p36/lib/python3.6/site-packages/IPython/core/ultratb.py\u001b[0m in \u001b[0;36mstructured_traceback\u001b[0;34m(self, etype, evalue, etb, tb_offset, number_of_lines_of_context)\u001b[0m\n\u001b[1;32m   1142\u001b[0m         \u001b[0mexception\u001b[0m \u001b[0;34m=\u001b[0m \u001b[0mself\u001b[0m\u001b[0;34m.\u001b[0m\u001b[0mget_parts_of_chained_exception\u001b[0m\u001b[0;34m(\u001b[0m\u001b[0mevalue\u001b[0m\u001b[0;34m)\u001b[0m\u001b[0;34m\u001b[0m\u001b[0m\n\u001b[1;32m   1143\u001b[0m         \u001b[0;32mif\u001b[0m \u001b[0mexception\u001b[0m\u001b[0;34m:\u001b[0m\u001b[0;34m\u001b[0m\u001b[0m\n\u001b[0;32m-> 1144\u001b[0;31m             \u001b[0mformatted_exceptions\u001b[0m \u001b[0;34m+=\u001b[0m \u001b[0mself\u001b[0m\u001b[0;34m.\u001b[0m\u001b[0mprepare_chained_exception_message\u001b[0m\u001b[0;34m(\u001b[0m\u001b[0mevalue\u001b[0m\u001b[0;34m.\u001b[0m\u001b[0m__cause__\u001b[0m\u001b[0;34m)\u001b[0m\u001b[0;34m\u001b[0m\u001b[0m\n\u001b[0m\u001b[1;32m   1145\u001b[0m             \u001b[0metype\u001b[0m\u001b[0;34m,\u001b[0m \u001b[0mevalue\u001b[0m\u001b[0;34m,\u001b[0m \u001b[0metb\u001b[0m \u001b[0;34m=\u001b[0m \u001b[0mexception\u001b[0m\u001b[0;34m\u001b[0m\u001b[0m\n\u001b[1;32m   1146\u001b[0m         \u001b[0;32melse\u001b[0m\u001b[0;34m:\u001b[0m\u001b[0;34m\u001b[0m\u001b[0m\n",
      "\u001b[0;31mTypeError\u001b[0m: must be str, not list"
     ]
    }
   ],
   "source": [
    "from keras import layers\n",
    "from keras import models"
   ]
  },
  {
   "cell_type": "code",
   "execution_count": null,
   "metadata": {},
   "outputs": [],
   "source": [
    "model -"
   ]
  }
 ],
 "metadata": {
  "kernelspec": {
   "display_name": "Python [conda env:tensorflow_p36]",
   "language": "python",
   "name": "conda-env-tensorflow_p36-py"
  },
  "language_info": {
   "codemirror_mode": {
    "name": "ipython",
    "version": 3
   },
   "file_extension": ".py",
   "mimetype": "text/x-python",
   "name": "python",
   "nbconvert_exporter": "python",
   "pygments_lexer": "ipython3",
   "version": "3.6.6"
  }
 },
 "nbformat": 4,
 "nbformat_minor": 2
}
